<mujoco model="ur5e scene">
  <compiler angle="radian" meshdir="assets/"/>

  <option integrator="implicitfast"/>

  <size nkey="1"/>

  <visual>
    <global azimuth="120" elevation="-20"/>
    <headlight diffuse="0.6 0.6 0.6" specular="0 0 0"/>
  </visual>

  <statistic meansize="0.08" extent="0.8" center="0.3 0 0.3"/>

  <default>
    <default class="ur5e">
      <material shininess="0.25"/>
      <joint range="-6.28319 6.28319" armature="0.1"/>
      <site size="0.001 0.005 0.005" group="4" rgba="0.5 0.5 0.5 0.3"/>
      <general ctrlrange="-6.2831 6.2831" forcerange="-150 150" biastype="affine" gainprm="2000" biasprm="0 -2000 -400"/>
      <default class="size3">
        <default class="size3_limited">
          <joint range="-3.1415 3.1415"/>
          <general ctrlrange="-3.1415 3.1415"/>
        </default>
      </default>
      <default class="size1">
        <general forcerange="-28 28" gainprm="500" biasprm="0 -500 -100"/>
      </default>
      <default class="visual">
        <geom type="mesh" contype="0" conaffinity="0" group="2"/>
      </default>
      <default class="collision">
        <geom type="capsule" group="3"/>
        <default class="eef_collision">
          <geom type="cylinder"/>
        </default>
      </default>
      <default class="active_adhesion">
        <geom size="3.4 3.4 3.4" margin="0.01" gap="0.01" rgba="0.1 0 0.5 1"/>
      </default>
    </default>
  </default>

  <asset>
    <texture type="2d" name="grid" builtin="checker" mark="cross" rgb1="0.2 0.3 0.4" rgb2="0.1 0.15 0.2" markrgb="0.8 0.8 0.8" width="512" height="512"/>
    <material name="black" class="ur5e" rgba="0.033 0.033 0.033 1"/>
    <material name="jointgray" class="ur5e" rgba="0.278 0.278 0.278 1"/>
    <material name="linkgray" class="ur5e" rgba="0.82 0.82 0.82 1"/>
    <material name="urblue" class="ur5e" rgba="0.49 0.678 0.8 1"/>
    <material name="grid" texture="grid" texuniform="true"/>
    <material name="metal_material" specular="0.6" shininess="0.4" rgba="0.7 0.7 0.7 1"/>
    <mesh name="base_0" file="base_0.obj"/>
    <mesh name="base_1" file="base_1.obj"/>
    <mesh name="shoulder_0" file="shoulder_0.obj"/>
    <mesh name="shoulder_1" file="shoulder_1.obj"/>
    <mesh name="shoulder_2" file="shoulder_2.obj"/>
    <mesh name="upperarm_0" file="upperarm_0.obj"/>
    <mesh name="upperarm_1" file="upperarm_1.obj"/>
    <mesh name="upperarm_2" file="upperarm_2.obj"/>
    <mesh name="upperarm_3" file="upperarm_3.obj"/>
    <mesh name="forearm_0" file="forearm_0.obj"/>
    <mesh name="forearm_1" file="forearm_1.obj"/>
    <mesh name="forearm_2" file="forearm_2.obj"/>
    <mesh name="forearm_3" file="forearm_3.obj"/>
    <mesh name="wrist1_0" file="wrist1_0.obj"/>
    <mesh name="wrist1_1" file="wrist1_1.obj"/>
    <mesh name="wrist1_2" file="wrist1_2.obj"/>
    <mesh name="wrist2_0" file="wrist2_0.obj"/>
    <mesh name="wrist2_1" file="wrist2_1.obj"/>
    <mesh name="wrist2_2" file="wrist2_2.obj"/>
    <mesh name="wrist3" file="wrist3.obj"/>
  </asset>

  <worldbody>
    <geom size="10 10 0.1" type="plane" solimp="0.99 0.99 0.01" material="grid"/>
    <light name="spotlight" target="wrist_2_link" pos="0 -1 2" dir="0 0 -1" mode="targetbodycom"/>
    <light pos="0 0 1.5" dir="0 0 -1" directional="true"/>
    <body name="base" childclass="ur5e" pos="0.8 0 0" quat="0.707107 0 0 0.707107">
      <inertial pos="0 0 0" mass="4" diaginertia="0.00443333 0.00443333 0.0072"/>
      <geom class="visual" material="black" mesh="base_0"/>
      <geom class="visual" material="jointgray" mesh="base_1"/>
      <body name="shoulder_link" pos="0 0 0.163">
        <inertial pos="0 0 0" mass="3.7" diaginertia="0.0102675 0.0102675 0.00666"/>
        <joint name="shoulder_pan_joint" class="size3" pos="0 0 0" axis="0 0 1"/>
        <geom class="visual" material="urblue" mesh="shoulder_0"/>
        <geom class="visual" material="black" mesh="shoulder_1"/>
        <geom class="visual" material="jointgray" mesh="shoulder_2"/>
        <geom class="collision" size="0.06 0.06" pos="0 0 -0.04"/>
        <body name="upper_arm_link" pos="0 0.138 0" quat="0.707107 0 0.707107 0">
          <inertial pos="0 0 0.2125" mass="8.393" diaginertia="0.133886 0.133886 0.0151074"/>
          <joint name="shoulder_lift_joint" class="size3" pos="0 0 0" axis="0 1 0"/>
          <geom class="visual" material="linkgray" mesh="upperarm_0"/>
          <geom class="visual" material="black" mesh="upperarm_1"/>
          <geom class="visual" material="jointgray" mesh="upperarm_2"/>
          <geom class="visual" material="urblue" mesh="upperarm_3"/>
          <geom class="collision" size="0.06 0.06" pos="0 -0.04 0" quat="0.707107 0.707107 0 0"/>
          <geom class="collision" size="0.05 0.2" pos="0 0 0.2"/>
          <body name="forearm_link" pos="0 -0.131 0.425">
            <inertial pos="0 0 0.196" mass="2.275" diaginertia="0.0311796 0.0311796 0.004095"/>
            <joint name="elbow_joint" class="size3_limited" pos="0 0 0" axis="0 1 0"/>
            <geom class="visual" material="urblue" mesh="forearm_0"/>
            <geom class="visual" material="linkgray" mesh="forearm_1"/>
            <geom class="visual" material="black" mesh="forearm_2"/>
            <geom class="visual" material="jointgray" mesh="forearm_3"/>
            <geom class="collision" size="0.055 0.06" pos="0 0.08 0" quat="0.707107 0.707107 0 0"/>
            <geom class="collision" size="0.038 0.19" pos="0 0 0.2"/>
            <body name="wrist_1_link" pos="0 0 0.392" quat="0.707107 0 0.707107 0">
              <inertial pos="0 0.127 0" mass="1.219" diaginertia="0.0025599 0.0025599 0.0021942"/>
              <joint name="wrist_1_joint" class="size1" pos="0 0 0" axis="0 1 0"/>
              <geom class="visual" material="black" mesh="wrist1_0"/>
              <geom class="visual" material="urblue" mesh="wrist1_1"/>
              <geom class="visual" material="jointgray" mesh="wrist1_2"/>
              <geom class="collision" size="0.04 0.07" pos="0 0.05 0" quat="0.707107 0.707107 0 0"/>
              <body name="wrist_2_link" pos="0 0.127 0">
                <inertial pos="0 0 0.1" mass="1.219" diaginertia="0.0025599 0.0025599 0.0021942"/>
                <joint name="wrist_2_joint" class="size1" pos="0 0 0" axis="0 0 1"/>
                <geom class="visual" material="black" mesh="wrist2_0"/>
                <geom class="visual" material="urblue" mesh="wrist2_1"/>
                <geom class="visual" material="jointgray" mesh="wrist2_2"/>
                <geom class="collision" size="0.04 0.06" pos="0 0 0.04"/>
                <geom class="collision" size="0.04 0.04" pos="0 0.02 0.1" quat="0.707107 0.707107 0 0"/>
                <body name="wrist_3_link" pos="0 0 0.1">
                  <inertial pos="0 0.0771683 0" quat="0.707107 0 0 0.707107" mass="0.1889" diaginertia="0.000132134 9.90863e-05 9.90863e-05"/>
                  <joint name="wrist_3_joint" class="size1" pos="0 0 0" axis="0 1 0"/>
                  <geom class="visual" material="linkgray" mesh="wrist3"/>
                  <geom name="adhesion_gripper" size="0.001" pos="0 0.08 0" priority="2" margin="0.01" gap="0.01" rgba="0.8 0.5 0.5 1"/>
                  <body name="4boxes" childclass="active_adhesion" pos="0.002 0.12 0" quat="0.707107 0.707107 0 0">
                    <joint name="arm3" pos="0 -0.03 0" axis="0 1 0" damping="0.01"/>
                    <geom size="0.015" pos="0.015 0.015 0"/>
                    <geom size="0.015" pos="0.015 -0.015 0"/>
                    <geom size="0.015" pos="-0.015 0.015 0"/>
                    <geom size="0.015" pos="-0.015 -0.015 0"/>
                    <site name="attachment_site" pos="0 0.1 0" rgba="1 0 0 1"/>
                  </body>
                </body>
              </body>
            </body>
          </body>
        </body>
      </body>
    </body>
    <body name="slab_mocap" pos="1 0.5 0.01" mocap="true">
      <geom name="slab" size="0.35 0.15 0.01" type="box" rgba="0.5 0.5 1 0.3"/>
    </body>
    <body name="frame_base" pos="-0.15 -0.3 0" quat="0.707107 0 0 0.707107">
      <inertial pos="0 0 0" mass="1" diaginertia="0.001 0.001 0.001"/>
      <geom name="base_beam" size="0.6 0.02 0.01" pos="0 0 0.01" type="box" solimp="0.9 0.95 0.01" material="metal_material"/>
      <geom name="base_stage" size="0.4 0.3 0.01" pos="0.1 0 0.2" type="box" solimp="0.9 0.95 0.01" material="metal_material"/>
      <body name="horizontal_support1" pos="0 0 0.01">
        <inertial pos="0 0 0" mass="1" diaginertia="0.001 0.001 0.001"/>
        <geom name="horizontal_beam1" size="0.02 0.5 0.02" pos="-0.2 0 0" quat="0.707107 0 0.707107 0" type="box" solimp="0.9 0.95 0.01" material="metal_material"/>
        <body name="vertical_support1">
          <inertial pos="0 0 0" mass="1" diaginertia="0.001 0.001 0.001"/>
          <geom name="vertical_beam1" size="0.02 0.8 0.02" pos="-0.15 0.3 0" quat="0 0 0.707107 0.707107" type="box" solimp="0.9 0.95 0.01" material="metal_material"/>
          <body name="angled_bar2" pos="0 0 0.1">
            <inertial pos="0 0 0" mass="1" diaginertia="0.001 0.001 0.001"/>
            <geom name="angled_beam2" size="0.02 0.7 0.02" pos="-0.15 0 0.175" quat="0.924261 0.38176 0 0" type="box" solimp="0.9 0.95 0.01" material="metal_material"/>
          </body>
        </body>
      </body>
      <body name="horizontal_support2" pos="0 0 0.01">
        <inertial pos="0 0 0" mass="1" diaginertia="0.001 0.001 0.001"/>
        <geom name="horizontal_beam2" size="0.02 0.5 0.02" pos="0.5 0 0" quat="-0.707107 0 0.707107 0" type="box" solimp="0.9 0.95 0.01" material="metal_material"/>
        <body name="angled_bar3" pos="0.8 0 0.1">
          <inertial pos="0 0 0" mass="1" diaginertia="0.001 0.001 0.001"/>
          <geom name="angled_beam3" size="0.02 0.7 0.02" pos="-0.3 0 0.175" quat="0.924261 0.38176 0 0" type="box" solimp="0.9 0.95 0.01" material="metal_material"/>
        </body>
        <body name="vertical_support2">
          <inertial pos="0 0 0" mass="1" diaginertia="0.001 0.001 0.001"/>
          <geom name="vertical_beam2" size="0.02 0.8 0.02" pos="0.5 0.3 0" quat="0 0 -0.707107 0.707107" type="box" solimp="0.9 0.95 0.01" material="metal_material"/>
        </body>
      </body>
    </body>
  </worldbody>

  <actuator>
    <general name="shoulder_pan" class="size3" joint="shoulder_pan_joint"/>
    <general name="shoulder_lift" class="size3" joint="shoulder_lift_joint"/>
    <general name="elbow" class="size3_limited" joint="elbow_joint"/>
    <general name="wrist_1" class="size1" joint="wrist_1_joint"/>
    <general name="wrist_2" class="size1" joint="wrist_2_joint"/>
    <general name="wrist_3" class="size1" joint="wrist_3_joint"/>
    <general name="adhere_wrist" body="4boxes" ctrllimited="true" ctrlrange="0 1" gainprm="1050"/>
  </actuator>

  <sensor>
    <jointpos joint="shoulder_pan_joint" name="shoulder_pan_pos"/>
    <jointpos joint="shoulder_lift_joint" name="shoulder_lift_pos"/>
    <jointpos joint="elbow_joint" name="elbow_pos"/>
    <jointpos joint="wrist_1_joint" name="wrist_1_pos"/>
    <jointpos joint="wrist_2_joint" name="wrist_2_pos"/>
    <jointpos joint="wrist_3_joint" name="wrist_3_pos"/>
    <jointvel joint="shoulder_pan_joint" name="shoulder_pan_vel"/>
    <jointvel joint="shoulder_lift_joint" name="shoulder_lift_vel"/>
    <jointvel joint="elbow_joint" name="elbow_vel"/>
    <jointvel joint="wrist_1_joint" name="wrist_1_vel"/>
    <jointvel joint="wrist_2_joint" name="wrist_2_vel"/>
    <jointvel joint="wrist_3_joint" name="wrist_3_vel"/>
  </sensor>

  <keyframe>
    <key name="home" time="3.02" qpos="-1.5708 -1.56258 1.57886 -1.56794 -1.5708 -4.24722e-08 -3.2969e-10" qvel="6.19139e-10 8.58291e-09 8.01964e-09 2.33301e-09 0 0 3.73655e-11" ctrl="-1.5708 -1.5708 1.5708 -1.5708 -1.5708 0 0"/>
  </keyframe>
</mujoco>
